Workbook

Sheet NAME
A1: Name | B1: BITS ID
A2: Keya Shah | B2: 2022ABPS1080P
A3: Sulakshya Mishra | B3: 2022B4TS1522P
A4: Anshuman Gupta | B4: 2022B3TS1519P
A5: Pranjal Jayaswal | B5: 2022B2TS1533P
A6: Renaissance Mukhopadhyay | B6: 2022A1PS0824P
A7: Jay Mittal | B7: 2021B4A41356P

Sheet Raw Data and Daily Price Change
M1: LOGARITHMIC PRICE CHANGES
A2: Date | B2: BASF | C2: RELIANCE | D2: HDFCBANK | E2: SUNPHARMA | F2: LT | G2: BASF Daily Returns | H2: RELIANCE Daily Returns | I2: HDFC BANK Daily Returns | J2: SUNPHARMA Daily Returns | K2: LT Daily Returns | L2: Logarithmic Price Change | M2: BASF logarithmic daily price change | N2: RELIANCE logarithmic daily Price Change | O2: HDFCBANK logarithmic daily Price Change | P2: SUNPHARMA logarithmic Daily Price Change | Q2: LT Logarithmic Daily Price Change | T2: Daily Mean Returns | W2: Daily Std Dev
A3: 44287 | B3: 2136.8999 | C3: 1866.1669 | D3: 1499.4 | E3: 610.75 | F3: 1432 | T3: BASF | U3: =AVERAGE(G4:G742) -> 0.00080359092 | W3: BASF | X3: =_xlfn.STDEV.S(G$4:G$742) -> 0.020219182
A4: 44291 | B4: 2034.95 | C4: 1839.1692 | D4: 1480 | E4: 608.79999 | F4: 1439 | G4: =(B4-B3)/B3 -> -0.047709278 | H4: =(C4-C3)/C3 -> -0.014466917 | I4: =(D4-D3)/D3 -> -0.012938525 | J4: =(E4-E3)/E3 -> -0.0031928154 | K4: =(F4-F3)/F3 -> 0.0048882682 | M4: =LN((B4/B3)) -> -0.04888491 | N4: =LN((C4/C3)) -> -0.014572583 | O4: =LN((D4/D3)) -> -0.013022956 | P4: =LN((E4/E3)) -> -0.0031979233 | Q4: =LN((F4/F3)) -> 0.0048763594 | T4: RELIANCE | U4: =AVERAGE(H4:H742) -> 0.00073487259 | W4: RELIANCE | X4: =_xlfn.STDEV.S(H4:H742) -> 0.014527249
A5: 44292 | B5: 2101.6499 | C5: 1831.5083 | D5: 1460 | E5: 620.45001 | F5: 1405.9 | G5: =(B5-B4)/B4 -> 0.032777195 | H5: =(C5-C4)/C4 -> -0.0041654069 | I5: =(D5-D4)/D4 -> -0.013513514 | J5: =(E5-E4)/E4 -> 0.019136045 | K5: =(F5-F4)/F4 -> -0.023002068 | M5: =LN((B5/B4)) -> 0.032251479 | N5: =LN((C5/C4)) -> -0.0041741064 | O5: =LN((D5/D4)) -> -0.013605652 | P5: =LN((E5/E4)) -> 0.018955254 | Q5: =LN((F5/F4)) -> -0.023270744 | T5: HDFCBANK | U5: =AVERAGE(I4:I742) -> 5.6524028e-05 | W5: HDFCBANK | X5: =_xlfn.STDEV.S(I4:I742) -> 0.014882213
A6: 44293 | B6: 2094.95 | C6: 1848.6299 | D6: 1439.3 | E6: 621.04999 | F6: 1402 | G6: =(B6-B5)/B5 -> -0.0031879482 | H6: =(C6-C5)/C5 -> 0.0093483508 | I6: =(D6-D5)/D5 -> -0.014178049 | J6: =(E6-E5)/E5 -> 0.00096700135 | K6: =(F6-F5)/F5 -> -0.0027740408 | M6: =LN((B6/B5)) -> -0.0031930405 | N6: =LN((C6/C5)) -> 0.0093049253 | O6: =LN((D6/D5)) -> -0.014279517 | P6: =LN((E6/E5)) -> 0.00096653411 | Q6: =LN((F6/F5)) -> -0.0027778956 | T6: SUNPHARMA | U6: =AVERAGE(J4:J742) -> 0.0014092431 | W6: SUNPHARMA | X6: =_xlfn.STDEV.S(J4:J742) -> 0.013333389
A7: 44294 | B7: 2094.6499 | C7: 1850.9374 | D7: 1453 | E7: 614.25 | F7: 1410 | G7: =(B7-B6)/B6 -> -0.0001432249 | H7: =(C7-C6)/C6 -> 0.001248219 | I7: =(D7-D6)/D6 -> 0.0095184816 | J7: =(E7-E6)/E6 -> -0.01094918 | K7: =(F7-F6)/F6 -> 0.0057061341 | M7: =LN((B7/B6)) -> -0.00014323516 | N7: =LN((C7/C6)) -> 0.0012474407 | O7: =LN((D7/D6)) -> 0.0094734663 | P7: =LN((E7/E6)) -> -0.011009563 | Q7: =LN((F7/F6)) -> 0.0056899158 | T7: LT | U7: =AVERAGE(K4:K742) -> 0.0013930082 | W7: LT | X7: =_xlfn.STDEV.S(K4:K742) -> 0.014534747
A8: 44295 | B8: 2068.8 | C8: 1829.4315 | D8: 1426 | E8: 636.75 | F8: 1414 | G8: =(B8-B7)/B7 -> -0.012340894 | H8: =(C8-C7)/C7 -> -0.011618901 | I8: =(D8-D7)/D7 -> -0.018582244 | J8: =(E8-E7)/E7 -> 0.036630037 | K8: =(F8-F7)/F7 -> 0.0028368794 | M8: =LN((B8/B7)) -> -0.012417675 | N8: =LN((C8/C7)) -> -0.011686928 | O8: =LN((D8/D7)) -> -0.018757063 | P8: =LN((E8/E7)) -> 0.035975102 | Q8: =LN((F8/F7)) -> 0.0028328631
A9: 44298 | B9: 1940.4 | C9: 1763.9908 | D9: 1393 | E9: 619.34998 | F9: 1393.95 | G9: =(B9-B8)/B8 -> -0.062064976 | H9: =(C9-C8)/C8 -> -0.035771043 | I9: =(D9-D8)/D8 -> -0.023141655 | J9: =(E9-E8)/E8 -> -0.027326304 | K9: =(F9-F8)/F8 -> -0.014179667 | M9: =LN((B9/B8)) -> -0.064074603 | N9: =LN((C9/C8)) -> -0.036426506 | O9: =LN((D9/D8)) -> -0.023413627 | P9: =LN((E9/E8)) -> -0.027706612 | Q9: =LN((F9/F8)) -> -0.014281159 | T9: Annualised Mean Returns | W9: Annual Std Dev
A10: 44299 | B10: 2118.3501 | C10: 1783.0508 | D10: 1368 | E10: 627.34998 | F10: 1347.25 | G10: =(B10-B9)/B9 -> 0.091707932 | H10: =(C10-C9)/C9 -> 0.010805008 | I10: =(D10-D9)/D9 -> -0.017946877 | J10: =(E10-E9)/E9 -> 0.012916768 | K10: =(F10-F9)/F9 -> -0.033501885 | M10: =LN((B10/B9)) -> 0.08774338 | N10: =LN((C10/C9)) -> 0.010747051 | O10: =LN((D10/D9)) -> -0.018109876 | P10: =LN((E10/E9)) -> 0.012834058 | Q10: =LN((F10/F9)) -> -0.034075931 | T10: BASF | U10: =((1+U3)^252)-1 -> 0.22436653 | W10: BASF | X10: =X3*SQRT(252) -> 0.32096956
A11: 44301 | B11: 2083.5 | C11: 1794.5883 | D11: 1405 | E11: 633.25 | F11: 1378.95 | G11: =(B11-B10)/B10 -> -0.016451529 | H11: =(C11-C10)/C10 -> 0.0064706379 | I11: =(D11-D10)/D10 -> 0.027046784 | J11: =(E11-E10)/E10 -> 0.0094046772 | K11: =(F11-F10)/F10 -> 0.023529375 | M11: =LN((B11/B10)) -> -0.016588358 | N11: =LN((C11/C10)) -> 0.0064497932 | O11: =LN((D11/D10)) -> 0.026687484 | P11: =LN((E11/E10)) -> 0.0093607285 | Q11: =LN((F11/F10)) -> 0.023256827 | T11: RELIANCE | U11: =((1+U4)^252)-1 -> 0.20336269 | W11: RELIANCE | X11: =X4*SQRT(252) -> 0.23061292
A12: 44302 | B12: 2099.8999 | C12: 1783.3276 | D12: 1434.95 | E12: 646.04999 | F12: 1360.5 | G12: =(B12-B11)/B11 -> 0.0078713233 | H12: =(C12-C11)/C11 -> -0.0062747652 | I12: =(D12-D11)/D11 -> 0.021316691 | J12: =(E12-E11)/E11 -> 0.020213167 | K12: =(F12-F11)/F11 -> -0.01337971 | M12: =LN((B12/B11)) -> 0.007840506 | N12: =LN((C12/C11)) -> -0.0062945343 | O12: =LN((D12/D11)) -> 0.021092668 | P12: =LN((E12/E11)) -> 0.020011593 | Q12: =LN((F12/F11)) -> -0.013470025 | T12: HDFCBANK | U12: =((1+U5)^252)-1 -> 0.014345577 | W12: HDFCBANK | X12: =X5*SQRT(252) -> 0.2362478
A13: 44305 | B13: 2027.6 | C13: 1755.2684 | D13: 1390 | E13: 640.65002 | F13: 1340 | G13: =(B13-B12)/B12 -> -0.034430177 | H13: =(C13-C12)/C12 -> -0.015734183 | I13: =(D13-D12)/D12 -> -0.0313251 | J13: =(E13-E12)/E12 -> -0.0083584306 | K13: =(F13-F12)/F12 -> -0.01506799 | M13: =LN((B13/B12)) -> -0.035036862 | N13: =LN((C13/C12)) -> -0.01585928 | O13: =LN((D13/D12)) -> -0.031826224 | P13: =LN((E13/E12)) -> -0.0083935582 | Q13: =LN((F13/F12)) -> -0.015182665 | T13: SUNPHARMA | U13: =((1+U6)^252)-1 -> 0.42600846 | W13: SUNPHARMA | X13: =X6*SQRT(252) -> 0.21166099
A14: 44306 | B14: 2020.15 | C14: 1754.7609 | D14: 1425 | E14: 645.15002 | F14: 1320 | G14: =(B14-B13)/B13 -> -0.0036742711 | H14: =(C14-C13)/C13 -> -0.00028916888 | I14: =(D14-D13)/D13 -> 0.025179856 | J14: =(E14-E13)/E13 -> 0.0070241159 | K14: =(F14-F13)/F13 -> -0.014925373 | M14: =LN((B14/B13)) -> -0.0036810378 | N14: =LN((C14/C13)) -> -0.00028921069 | O14: =LN((D14/D13)) -> 0.024868067 | P14: =LN((E14/E13)) -> 0.0069995617 | Q14: =LN((F14/F13)) -> -0.015037877 | T14: LT | U14: =((1+U7)^252)-1 -> 0.42019443 | W14: LT | X14: =X7*SQRT(252) -> 0.23073196
A15: 44308 | B15: 2033 | C15: 1759.6066 | D15: 1380 | E15: 639.95001 | F15: 1310 | G15: =(B15-B14)/B14 -> 0.0063609018 | H15: =(C15-C14)/C14 -> 0.0027614606 | I15: =(D15-D14)/D14 -> -0.031578947 | J15: =(E15-E14)/E14 -> -0.0080601594 | K15: =(F15-F14)/F14 -> -0.0075757576 | M15: =LN((B15/B14)) -> 0.0063407567 | N15: =LN((C15/C14)) -> 0.0027576548 | O15: =LN((D15/D14)) -> -0.032088315 | P15: =LN((E15/E14)) -> -0.008092818 | Q15: =LN((F15/F14)) -> -0.0076045994
A16: 44309 | B16: 1969.65 | C16: 1757.7145 | D16: 1409 | E16: 637.95001 | F16: 1330 | G16: =(B16-B15)/B15 -> -0.031160834 | H16: =(C16-C15)/C15 -> -0.0010752909 | I16: =(D16-D15)/D15 -> 0.021014493 | J16: =(E16-E15)/E15 -> -0.0031252441 | K16: =(F16-F15)/F15 -> 0.015267176 | M16: =LN((B16/B15)) -> -0.03165666 | N16: =LN((C16/C15)) -> -0.0010758695 | O16: =LN((D16/D15)) -> 0.020796734 | P16: =LN((E16/E15)) -> -0.0031301379 | Q16: =LN((F16/F15)) -> 0.015151805 | T16: Coefficient of Variation
A17: 44312 | B17: 1977.5 | C17: 1788.6349 | D17: 1413 | E17: 634.70001 | F17: 1330.05 | G17: =(B17-B16)/B16 -> 0.0039854674 | H17: =(C17-C16)/C16 -> 0.017591259 | I17: =(D17-D16)/D16 -> 0.0028388928 | J17: =(E17-E16)/E16 -> -0.005094443 | K17: =(F17-F16)/F16 -> 3.7630827e-05 | M17: =LN((B17/B16)) -> 0.0039775465 | N17: =LN((C17/C16)) -> 0.017438323 | O17: =LN((D17/D16)) -> 0.0028348708 | P17: =LN((E17/E16)) -> -0.005107464 | Q17: =LN((F17/F16)) -> 3.7630119e-05 | T17: BASF | U17: =X10/U10 -> 1.430559
A18: 44313 | B18: 2014.8 | C18: 1835.5233 | D18: 1407.25 | E18: 639.25 | F18: 1339 | G18: =(B18-B17)/B17 -> 0.018862225 | H18: =(C18-C17)/C17 -> 0.026214644 | I18: =(D18-D17)/D17 -> -0.004069356 | J18: =(E18-E17)/E17 -> 0.0071687221 | K18: =(F18-F17)/F17 -> 0.0067290332 | M18: =LN((B18/B17)) -> 0.018686539 | N18: =LN((C18/C17)) -> 0.02587693 | O18: =LN((D18/D17)) -> -0.0040776583 | P18: =LN((E18/E17)) -> 0.007143149 | Q18: =LN((F18/F17)) -> 0.0067064944 | T18: RELIANCE | U18: =X11/U11 -> 1.1339982
A19: 44314 | B19: 2051.1499 | C19: 1843.5072 | D19: 1436.25 | E19: 643.40002 | F19: 1384.85 | G19: =(B19-B18)/B18 -> 0.01804142 | H19: =(C19-C18)/C18 -> 0.0043496516 | I19: =(D19-D18)/D18 -> 0.020607568 | J19: =(E19-E18)/E18 -> 0.0064920203 | K19: =(F19-F18)/F18 -> 0.034241954 | M19: =LN((B19/B18)) -> 0.017880604 | N19: =LN((C19/C18)) -> 0.0043402192 | O19: =LN((D19/D18)) -> 0.020398105 | P19: =LN((E19/E18)) -> 0.0064710379 | Q19: =LN((F19/F18)) -> 0.033668746 | T19: HDFCBANK | U19: =X12/U12 -> 16.468338
A20: 44315 | B20: 2073.95 | C20: 1868.1975 | D20: 1486.2 | E20: 644.5 | F20: 1383.95 | G20: =(B20-B19)/B19 -> 0.01111574 | H20: =(C20-C19)/C19 -> 0.013393117 | I20: =(D20-D19)/D19 -> 0.034778034 | J20: =(E20-E19)/E19 -> 0.00170963 | K20: =(F20-F19)/F19 -> -0.00064990794 | M20: =LN((B20/B19)) -> 0.011054414 | N20: =LN((C20/C19)) -> 0.013304222 | O20: =LN((D20/D19)) -> 0.034186944 | P20: =LN((E20/E19)) -> 0.0017081703 | Q20: =LN((F20/F19)) -> -0.00065011923 | T20: SUNPHARMA | U20: =X13/U13 -> 0.49684691
A21: 44316 | B21: 2228.75 | C21: 1840.9229 | D21: 1445 | E21: 654.45001 | F21: 1350 | G21: =(B21-B20)/B20 -> 0.074640205 | H21: =(C21-C20)/C20 -> -0.014599451 | I21: =(D21-D20)/D20 -> -0.027721674 | J21: =(E21-E20)/E20 -> 0.015438343 | K21: =(F21-F20)/F20 -> -0.024531199 | M21: =LN((B21/B20)) -> 0.071985912 | N21: =LN((C21/C20)) -> -0.014707072 | O21: =LN((D21/D20)) -> -0.028113172 | P21: =LN((E21/E20)) -> 0.015320384 | Q21: =LN((F21/F20)) -> -0.024837102 | T21: LT | U21: =X14/U14 -> 0.54910761
A22: 44319 | B22: 2282.8999 | C22: 1808.2025 | D22: 1393 | E22: 659.20001 | F22: 1325.5 | G22: =(B22-B21)/B21 -> 0.024296086 | H22: =(C22-C21)/C21 -> -0.017773877 | I22: =(D22-D21)/D21 -> -0.035986159 | J22: =(E22-E21)/E21 -> 0.0072580028 | K22: =(F22-F21)/F21 -> -0.018148148 | M22: =LN((B22/B21)) -> 0.024005631 | N22: =LN((C22/C21)) -> -0.01793373 | O22: =LN((D22/D21)) -> -0.036649627 | P22: =LN((E22/E21)) -> 0.0072317902 | Q22: =LN((F22/F21)) -> -0.018314846
A23: 44320 | B23: 2281.55 | C23: 1769.0211 | D23: 1409.95 | E23: 645.15002 | F23: 1350 | G23: =(B23-B22)/B22 -> -0.00059128874 | H23: =(C23-C22)/C22 -> -0.0216687 | I23: =(D23-D22)/D22 -> 0.012167948 | J23: =(E23-E22)/E22 -> -0.021313695 | K23: =(F23-F22)/F22 -> 0.018483591 | M23: =LN((B23/B22)) -> -0.00059146362 | N23: =LN((C23/C22)) -> -0.021906913 | O23: =LN((D23/D22)) -> 0.012094513 | P23: =LN((E23/E22)) -> -0.021544112 | Q23: =LN((F23/F22)) -> 0.018314846 | T23: Ranking Based on: | U23: Risk | V23: Return | W23: Coefficient of Variation
A24: 44321 | B24: 2320.7 | C24: 1772.2517 | D24: 1401 | E24: 683.40002 | F24: 1342.2 | G24: =(B24-B23)/B23 -> 0.017159344 | H24: =(C24-C23)/C23 -> 0.0018262026 | I24: =(D24-D23)/D23 -> -0.0063477083 | J24: =(E24-E23)/E23 -> 0.059288535 | K24: =(F24-F23)/F23 -> -0.0057778141 | M24: =LN((B24/B23)) -> 0.017013785 | N24: =LN((C24/C23)) -> 0.0018245371 | O24: =LN((D24/D23)) -> -0.0063679407 | P24: =LN((E24/E23)) -> 0.05759749 | Q24: =LN((F24/F23)) -> -0.0057945702 | T24: 1 | U24: SUNPHARMA | V24: SUNPHARMA | W24: SUNPHARMA
A25: 44322 | B25: 2294.8999 | C25: 1782.3124 | D25: 1407.6 | E25: 679.40002 | F25: 1344 | G25: =(B25-B24)/B24 -> -0.011117357 | H25: =(C25-C24)/C24 -> 0.0056767721 | I25: =(D25-D24)/D24 -> 0.0047109036 | J25: =(E25-E24)/E24 -> -0.0058530873 | K25: =(F25-F24)/F24 -> 0.0013411184 | M25: =LN((B25/B24)) -> -0.011179616 | N25: =LN((C25/C24)) -> 0.0056607199 | O25: =LN((D25/D24)) -> 0.0046998421 | P25: =LN((E25/E24)) -> -0.0058702837 | Q25: =LN((F25/F24)) -> 0.0013402199 | T25: 2 | U25: RELIANCE | V25: LT | W25: LT
A26: 44323 | B26: 2451.7 | C26: 1783.0046 | D26: 1412.95 | E26: 679.45001 | F26: 1347 | G26: =(B26-B25)/B25 -> 0.068325441 | H26: =(C26-C25)/C25 -> 0.0003884061 | I26: =(D26-D25)/D25 -> 0.003800778 | J26: =(E26-E25)/E25 -> 7.3576683e-05 | K26: =(F26-F25)/F25 -> 0.0022321429 | M26: =LN((B26/B25)) -> 0.066092415 | N26: =LN((C26/C25)) -> 0.00038833069 | O26: =LN((D26/D25)) -> 0.0037935733 | P26: =LN((E26/E25)) -> 7.3573976e-05 | Q26: =LN((F26/F25)) -> 0.0022296553 | T26: 3 | U26: LT | V26: BASF | W26: RELIANCE
A27: 44326 | B27: 2480.45 | C27: 1777.882 | D27: 1427 | E27: 698.20001 | F27: 1347 | G27: =(B27-B26)/B26 -> 0.011726557 | H27: =(C27-C26)/C26 -> -0.0028730609 | I27: =(D27-D26)/D26 -> 0.0099437698 | J27: =(E27-E26)/E26 -> 0.027595849 | K27: =(F27-F26)/F26 -> 0 | M27: =LN((B27/B26)) -> 0.011658334 | N27: =LN((C27/C26)) -> -0.0028771961 | O27: =LN((D27/D26)) -> 0.0098946558 | P27: =LN((E27/E26)) -> 0.027221947 | Q27: =LN((F27/F26)) -> 0 | T27: 4 | U27: HDFCBANK | V27: RELIANCE | W27: BASF
A28: 44327 | B28: 2493.6001 | C28: 1784.2969 | D28: 1396 | E28: 708.09998 | F28: 1380 | G28: =(B28-B27)/B27 -> 0.0053015168 | H28: =(C28-C27)/C27 -> 0.0036081794 | I28: =(D28-D27)/D27 -> -0.021723896 | J28: =(E28-E27)/E27 -> 0.014179266 | K28: =(F28-F27)/F27 -> 0.024498886 | M28: =LN((B28/B27)) -> 0.0052875132 | N28: =LN((C28/C27)) -> 0.0036016855 | O28: =LN((D28/D27)) -> -0.021963334 | P28: =LN((E28/E27)) -> 0.014079681 | Q28: =LN((F28/F27)) -> 0.024203602 | T28: 5 | U28: BASF | V28: HDFCBANK | W28: HDFCBANK
A29: 44328 | B29: 2409.6499 | C29: 1765.8368 | D29: 1399.75 | E29: 702.84998 | F29: 1380 | G29: =(B29-B28)/B28 -> -0.033666263 | H29: =(C29-C28)/C28 -> -0.010345859 | I29: =(D29-D28)/D28 -> 0.0026862464 | J29: =(E29-E28)/E28 -> -0.0074142073 | K29: =(F29-F28)/F28 -> 0 | M29: =LN((B29/B28)) -> -0.034246021 | N29: =LN((C29/C28)) -> -0.010399749 | O29: =LN((D29/D28)) -> 0.0026826449 | P29: =LN((E29/E28)) -> -0.0074418291 | Q29: =LN((F29/F28)) -> 0
A30: 44330 | B30: 2471.1499 | C30: 1788.1273 | D30: 1394.35 | E30: 691.45001 | F30: 1394 | G30: =(B30-B29)/B29 -> 0.02552238 | H30: =(C30-C29)/C29 -> 0.012623209 | I30: =(D30-D29)/D29 -> -0.0038578489 | J30: =(E30-E29)/E29 -> -0.016219626 | K30: =(F30-F29)/F29 -> 0.010144928 | M30: =LN((B30/B29)) -> 0.025202122 | N30: =LN((C30/C29)) -> 0.012544201 | O30: =LN((D30/D29)) -> -0.0038653096 | P30: =LN((E30/E29)) -> -0.016352604 | Q30: =LN((F30/F29)) -> 0.010093813
A31: 44333 | B31: 2389.45 | C31: 1809.4025 | D31: 1395.15 | E31: 687.15002 | F31: 1433 | G31: =(B31-B30)/B30 -> -0.033061512 | H31: =(C31-C30)/C30 -> 0.011898005 | I31: =(D31-D30)/D30 -> 0.00057377847 | J31: =(E31-E30)/E30 -> -0.0062187981 | K31: =(F31-F30)/F30 -> 0.027977044 | M31: =LN((B31/B30)) -> -0.033620396 | N31: =LN((C31/C30)) -> 0.01182778 | O31: =LN((D31/D30)) -> 0.00057361393 | P31: =LN((E31/E30)) -> -0.0062382153 | Q31: =LN((F31/F30)) -> 0.027592837
A32: 44334 | B32: 2497.55 | C32: 1834.8772 | D32: 1458.95 | E32: 690.79999 | F32: 1405 | G32: =(B32-B31)/B31 -> 0.045240578 | H32: =(C32-C31)/C31 -> 0.014079085 | I32: =(D32-D31)/D31 -> 0.045729797 | J32: =(E32-E31)/E31 -> 0.0053117425 | K32: =(F32-F31)/F31 -> -0.019539428 | M32: =LN((B32/B31)) -> 0.044247078 | N32: =LN((C32/C31)) -> 0.013980895 | O32: =LN((D32/D31)) -> 0.044715012 | P32: =LN((E32/E31)) -> 0.005297685 | Q32: =LN((F32/F31)) -> -0.019732846
A33: 44335 | B33: 2452.8 | C33: 1843.2765 | D33: 1470.2 | E33: 703.40002 | F33: 1414 | G33: =(B33-B32)/B32 -> -0.017917559 | H33: =(C33-C32)/C32 -> 0.0045775772 | I33: =(D33-D32)/D32 -> 0.0077110253 | J33: =(E33-E32)/E32 -> 0.018239774 | K33: =(F33-F32)/F32 -> 0.006405694 | M33: =LN((B33/B32)) -> -0.018080022 | N33: =LN((C33/C32)) -> 0.0045671319 | O33: =LN((D33/D32)) -> 0.0076814473 | P33: =LN((E33/E32)) -> 0.018075425 | Q33: =LN((F33/F32)) -> 0.0063852647
A34: 44336 | B34: 2465.95 | C34: 1832.5236 | D34: 1458.35 | E34: 686.84998 | F34: 1410.8 | G34: =(B34-B33)/B33 -> 0.0053611798 | H34: =(C34-C33)/C33 -> -0.0058335953 | I34: =(D34-D33)/D33 -> -0.0080601111 | J34: =(E34-E33)/E33 -> -0.023528643 | K34: =(F34-F33)/F33 -> -0.0022630488 | M34: =LN((B34/B33)) -> 0.0053468598 | N34: =LN((C34/C33)) -> -0.0058506771 | O34: =LN((D34/D33)) -> -0.0080927694 | P34: =LN((E34/E33)) -> -0.023809861 | Q34: =LN((F34/F33)) -> -0.0022656134
A35: 44337 | B35: 2443.55 | C35: 1848.353 | D35: 1443 | E35: 690.40002 | F35: 1415 | G35: =(B35-B34)/B34 -> -0.0090836807 | H35: =(C35-C34)/C34 -> 0.0086380701 | I35: =(D35-D34)/D34 -> -0.010525578 | J35: =(E35-E34)/E34 -> 0.005168593 | K35: =(F35-F34)/F34 -> 0.0029769995 | M35: =LN((B35/B34)) -> -0.0091251889 | N35: =LN((C35/C34)) -> 0.0086009755 | O35: =LN((D35/D34)) -> -0.010581363 | P35: =LN((E35/E34)) -> 0.0051552817 | Q35: =LN((F35/F34)) -> 0.002972577
A36: 44340 | B36: 2405.3501 | C36: 1832.7543 | D36: 1503.25 | E36: 690.95001 | F36: 1420 | G36: =(B36-B35)/B35 -> -0.015632973 | H36: =(C36-C35)/C35 -> -0.0084392726 | I36: =(D36-D35)/D35 -> 0.041753292 | J36: =(E36-E35)/E35 -> 0.00079662222 | K36: =(F36-F35)/F35 -> 0.0035335689 | M36: =LN((B36/B35)) -> -0.015756456 | N36: =LN((C36/C35)) -> -0.0084750849 | O36: =LN((D36/D35)) -> 0.040905151 | P36: =LN((E36/E35)) -> 0.00079630509 | Q36: =LN((F36/F35)) -> 0.0035273405
A37: 44341 | B37: 2403.5 | C37: 1811.9868 | D37: 1510.5 | E37: 696.09998 | F37: 1460 | G37: =(B37-B36)/B36 -> -0.00076915955 | H37: =(C37-C36)/C36 -> -0.011331282 | I37: =(D37-D36)/D36 -> 0.0048228838 | J37: =(E37-E36)/E36 -> 0.0074534538 | K37: =(F37-F36)/F36 -> 0.028169014 | M37: =LN((B37/B36)) -> -0.00076945551 | N37: =LN((C37/C36)) -> -0.01139597 | O37: =LN((D37/D36)) -> 0.0048112909 | P37: =LN((E37/E36)) -> 0.0074258141 | Q37: =LN((F37/F36)) -> 0.027779564
A38: 44342 | B38: 2340.05 | C38: 1818.3555 | D38: 1480 | E38: 703.79999 | F38: 1458.9 | G38: =(B38-B37)/B37 -> -0.026398981 | H38: =(C38-C37)/C37 -> 0.0035147347 | I38: =(D38-D37)/D37 -> -0.020191989 | J38: =(E38-E37)/E37 -> 0.011061647 | K38: =(F38-F37)/F37 -> -0.00075340822 | M38: =LN((B38/B37)) -> -0.026753691 | N38: =LN((C38/C37)) -> 0.0035085725 | O38: =LN((D38/D37)) -> -0.020398634 | P38: =LN((E38/E37)) -> 0.011000914 | Q38: =LN((F38/F37)) -> -0.00075369217
A39: 44343 | B39: 2374.05 | C39: 1823.9397 | D39: 1473.1 | E39: 699.5 | F39: 1475.95 | G39: =(B39-B38)/B38 -> 0.014529604 | H39: =(C39-C38)/C38 -> 0.0030710321 | I39: =(D39-D38)/D38 -> -0.0046621784 | J39: =(E39-E38)/E38 -> -0.0061096733 | K39: =(F39-F38)/F38 -> 0.011686837 | M39: =LN((B39/B38)) -> 0.014425061 | N39: =LN((C39/C38)) -> 0.0030663261 | O39: =LN((D39/D38)) -> -0.0046730802 | P39: =LN((E39/E38)) -> -0.0061284137 | Q39: =LN((F39/F38)) -> 0.011619074
A40: 44344 | B40: 2364.7 | C40: 1933.4998 | D40: 1490.9 | E40: 669.75 | F40: 1487.1 | G40: =(B40-B39)/B39 -> -0.0039384587 | H40: =(C40-C39)/C39 -> 0.060067808 | I40: =(D40-D39)/D39 -> 0.012083394 | J40: =(E40-E39)/E39 -> -0.042530379 | K40: =(F40-F39)/F39 -> 0.0075544736 | M40: =LN((B40/B39)) -> -0.0039462348 | N40: =LN((C40/C39)) -> 0.058332876 | O40: =LN((D40/D39)) -> 0.012010973 | P40: =LN((E40/E39)) -> -0.043461286 | Q40: =LN((F40/F39)) -> 0.0075260815
...

Sheet 2.b Portfolios Daily Value
A1: Date | B1: BASF | C1: RELAINCE | D1: HDFCBANK | E1: SUNPHARMA | F1: LT | H1: PORTFOLIO1 VALUE | I1: Portfolio1 Returns | J1: Portfolio2 Value | K1: Portfolio2 Retuns
A2: 44287 | B2: 2136.8999 | C2: 1866.1669 | D2: 1499.4 | E2: 610.75 | F2: 1432 | H2: =(B2*0.3+C2*'Price weighted Portfolio'!$B$22+'2.b Portfolios Daily Value'!D2*'Price weighted Portfolio'!$B$23+'2.b Portfolios Daily Value'!E2*'Price weighted Portfolio'!$B$24+'2.b Portfolios Daily Value'!F2*'Price weighted Portfolio'!$B$25) -> 1807.1465 | J2: =B2*$Q$10+C2*$Q$6+D2*$Q$7+E2*$Q$8+F2*$Q$9 -> 1185.3585
A3: 44291 | B3: 2034.95 | C3: 1839.1692 | D3: 1480 | E3: 608.79999 | F3: 1439 | H3: =(B3*0.3+C3*'Price weighted Portfolio'!$B$22+'2.b Portfolios Daily Value'!D3*'Price weighted Portfolio'!$B$23+'2.b Portfolios Daily Value'!E3*'Price weighted Portfolio'!$B$24+'2.b Portfolios Daily Value'!F3*'Price weighted Portfolio'!$B$25) -> 1764.1896 | I3: =(H3/$H$2)-1 -> -0.023770546 | J3: =B3*$Q$10+C3*$Q$6+D3*$Q$7+E3*$Q$8+F3*$Q$9 -> 1152.4782 | K3: =(J3/$J$2)-1 -> -0.027738771 | M3: Portfolio Based on Price Index | P3: Portfolio Based on Correlation Matrix
A4: 44292 | B4: 2101.6499 | C4: 1831.5083 | D4: 1460 | E4: 620.45001 | F4: 1405.9 | H4: =(B4*0.3+C4*'Price weighted Portfolio'!$B$22+'2.b Portfolios Daily Value'!D4*'Price weighted Portfolio'!$B$23+'2.b Portfolios Daily Value'!E4*'Price weighted Portfolio'!$B$24+'2.b Portfolios Daily Value'!F4*'Price weighted Portfolio'!$B$25) -> 1776.5404 | I4: =(H4/$H$2)-1 -> -0.016936142 | J4: =B4*$Q$10+C4*$Q$6+D4*$Q$7+E4*$Q$8+F4*$Q$9 -> 1165.5499 | K4: =(J4/$J$2)-1 -> -0.01671109
A5: 44293 | B5: 2094.95 | C5: 1848.6299 | D5: 1439.3 | E5: 621.04999 | F5: 1402 | H5: =(B5*0.3+C5*'Price weighted Portfolio'!$B$22+'2.b Portfolios Daily Value'!D5*'Price weighted Portfolio'!$B$23+'2.b Portfolios Daily Value'!E5*'Price weighted Portfolio'!$B$24+'2.b Portfolios Daily Value'!F5*'Price weighted Portfolio'!$B$25) -> 1779.4942 | I5: =(H5/$H$2)-1 -> -0.015301606 | J5: =B5*$Q$10+C5*$Q$6+D5*$Q$7+E5*$Q$8+F5*$Q$9 -> 1162.1524 | K5: =(J5/$J$2)-1 -> -0.019577301 | M5: Stock | N5: Price | P5: Stock | Q5: Weight
A6: 44294 | B6: 2094.6499 | C6: 1850.9374 | D6: 1453 | E6: 614.25 | F6: 1410 | H6: =(B6*0.3+C6*'Price weighted Portfolio'!$B$22+'2.b Portfolios Daily Value'!D6*'Price weighted Portfolio'!$B$23+'2.b Portfolios Daily Value'!E6*'Price weighted Portfolio'!$B$24+'2.b Portfolios Daily Value'!F6*'Price weighted Portfolio'!$B$25) -> 1781.7316 | I6: =(H6/$H$2)-1 -> -0.01406352 | J6: =B6*$Q$10+C6*$Q$6+D6*$Q$7+E6*$Q$8+F6*$Q$9 -> 1164.2009 | K6: =(J6/$J$2)-1 -> -0.017849189 | M6: RELIANCE | N6: =('Price weighted Portfolio'!B6/'Price weighted Portfolio'!$B$12)*0.7 -> 0.060911085 | P6: RELIANCE | Q6: =N6 -> 0.060911085
A7: 44295 | B7: 2068.8 | C7: 1829.4315 | D7: 1426 | E7: 636.75 | F7: 1414 | H7: =(B7*0.3+C7*'Price weighted Portfolio'!$B$22+'2.b Portfolios Daily Value'!D7*'Price weighted Portfolio'!$B$23+'2.b Portfolios Daily Value'!E7*'Price weighted Portfolio'!$B$24+'2.b Portfolios Daily Value'!F7*'Price weighted Portfolio'!$B$25) -> 1765.8565 | I7: =(H7/$H$2)-1 -> -0.022848144 | J7: =B7*$Q$10+C7*$Q$6+D7*$Q$7+E7*$Q$8+F7*$Q$9 -> 1155.3922 | K7: =(J7/$J$2)-1 -> -0.025280389 | M7: HDFCBANK | N7: =('Price weighted Portfolio'!B7/'Price weighted Portfolio'!$B$12)*0.7 -> 0.085454699 | P7: HDFCBANK | Q7: =N8 -> 0.087325251
A8: 44298 | B8: 1940.4 | C8: 1763.9908 | D8: 1393 | E8: 619.34998 | F8: 1393.95 | H8: =(B8*0.3+C8*'Price weighted Portfolio'!$B$22+'2.b Portfolios Daily Value'!D8*'Price weighted Portfolio'!$B$23+'2.b Portfolios Daily Value'!E8*'Price weighted Portfolio'!$B$24+'2.b Portfolios Daily Value'!F8*'Price weighted Portfolio'!$B$25) -> 1692.4031 | I8: =(H8/$H$2)-1 -> -0.063494209 | J8: =B8*$Q$10+C8*$Q$6+D8*$Q$7+E8*$Q$8+F8*$Q$9 -> 1105.0523 | K8: =(J8/$J$2)-1 -> -0.06774851 | M8: SUNPHARMA | N8: =('Price weighted Portfolio'!B8/'Price weighted Portfolio'!$B$12)*0.7 -> 0.087325251 | P8: SUNPHARMA | Q8: =N7 -> 0.085454699
A9: 44299 | B9: 2118.3501 | C9: 1783.0508 | D9: 1368 | E9: 627.34998 | F9: 1347.25 | H9: =(B9*0.3+C9*'Price weighted Portfolio'!$B$22+'2.b Portfolios Daily Value'!D9*'Price weighted Portfolio'!$B$23+'2.b Portfolios Daily Value'!E9*'Price weighted Portfolio'!$B$24+'2.b Portfolios Daily Value'!F9*'Price weighted Portfolio'!$B$25) -> 1746.7546 | I9: =(H9/$H$2)-1 -> -0.033418382 | J9: =B9*$Q$10+C9*$Q$6+D9*$Q$7+E9*$Q$8+F9*$Q$9 -> 1150.0276 | K9: =(J9/$J$2)-1 -> -0.029806086 | M9: LT | N9: =('Price weighted Portfolio'!B9/'Price weighted Portfolio'!$B$12)*0.7 -> 0.17282917 | P9: LT | Q9: =N9 -> 0.17282917
A10: 44301 | B10: 2083.5 | C10: 1794.5883 | D10: 1405 | E10: 633.25 | F10: 1378.95 | H10: =(B10*0.3+C10*'Price weighted Portfolio'!$B$22+'2.b Portfolios Daily Value'!D10*'Price weighted Portfolio'!$B$23+'2.b Portfolios Daily Value'!E10*'Price weighted Portfolio'!$B$24+'2.b Portfolios Daily Value'!F10*'Price weighted Portfolio'!$B$25) -> 1749.0311 | I10: =(H10/$H$2)-1 -> -0.032158625 | J10: =B10*$Q$10+C10*$Q$6+D10*$Q$7+E10*$Q$8+F10*$Q$9 -> 1149.4893 | K10: =(J10/$J$2)-1 -> -0.030260273 | M10: BASF | N10: 0.3 | P10: BASF | Q10: 0.3
A11: 44302 | B11: 2099.8999 | C11: 1783.3276 | D11: 1434.95 | E11: 646.04999 | F11: 1360.5 | H11: =(B11*0.3+C11*'Price weighted Portfolio'!$B$22+'2.b Portfolios Daily Value'!D11*'Price weighted Portfolio'!$B$23+'2.b Portfolios Daily Value'!E11*'Price weighted Portfolio'!$B$24+'2.b Portfolios Daily Value'!F11*'Price weighted Portfolio'!$B$25) -> 1751.0971 | I11: =(H11/$H$2)-1 -> -0.031015408 | J11: =B11*$Q$10+C11*$Q$6+D11*$Q$7+E11*$Q$8+F11*$Q$9 -> 1154.2439 | K11: =(J11/$J$2)-1 -> -0.026249174 | N11: =SUM(N6:N10) -> 0.70652021 | Q11: =SUM(Q6:Q10) -> 0.70652021
A12: 44305 | B12: 2027.6 | C12: 1755.2684 | D12: 1390 | E12: 640.65002 | F12: 1340 | H12: =(B12*0.3+C12*'Price weighted Portfolio'!$B$22+'2.b Portfolios Daily Value'!D12*'Price weighted Portfolio'!$B$23+'2.b Portfolios Daily Value'!E12*'Price weighted Portfolio'!$B$24+'2.b Portfolios Daily Value'!F12*'Price weighted Portfolio'!$B$25) -> 1710.5152 | I12: =(H12/$H$2)-1 -> -0.053471777 | J12: =B12*$Q$10+C12*$Q$6+D12*$Q$7+E12*$Q$8+F12*$Q$9 -> 1122.915 | K12: =(J12/$J$2)-1 -> -0.052678992
A13: 44306 | B13: 2020.15 | C13: 1754.7609 | D13: 1425 | E13: 645.15002 | F13: 1320 | H13: =(B13*0.3+C13*'Price weighted Portfolio'!$B$22+'2.b Portfolios Daily Value'!D13*'Price weighted Portfolio'!$B$23+'2.b Portfolios Daily Value'!E13*'Price weighted Portfolio'!$B$24+'2.b Portfolios Daily Value'!F13*'Price weighted Portfolio'!$B$25) -> 1709.1673 | I13: =(H13/$H$2)-1 -> -0.054217643 | J13: =B13*$Q$10+C13*$Q$6+D13*$Q$7+E13*$Q$8+F13*$Q$9 -> 1120.6335 | K13: =(J13/$J$2)-1 -> -0.054603773
A14: 44308 | B14: 2033 | C14: 1759.6066 | D14: 1380 | E14: 639.95001 | F14: 1310 | H14: =(B14*0.3+C14*'Price weighted Portfolio'!$B$22+'2.b Portfolios Daily Value'!D14*'Price weighted Portfolio'!$B$23+'2.b Portfolios Daily Value'!E14*'Price weighted Portfolio'!$B$24+'2.b Portfolios Daily Value'!F14*'Price weighted Portfolio'!$B$25) -> 1709.2558 | I14: =(H14/$H$2)-1 -> -0.054168636 | J14: =B14*$Q$10+C14*$Q$6+D14*$Q$7+E14*$Q$8+F14*$Q$9 -> 1118.6813 | K14: =(J14/$J$2)-1 -> -0.056250654
A15: 44309 | B15: 1969.65 | C15: 1757.7145 | D15: 1409 | E15: 637.95001 | F15: 1330 | H15: =(B15*0.3+C15*'Price weighted Portfolio'!$B$22+'2.b Portfolios Daily Value'!D15*'Price weighted Portfolio'!$B$23+'2.b Portfolios Daily Value'!E15*'Price weighted Portfolio'!$B$24+'2.b Portfolios Daily Value'!F15*'Price weighted Portfolio'!$B$25) -> 1694.2319 | I15: =(H15/$H$2)-1 -> -0.06248227 | J15: =B15*$Q$10+C15*$Q$6+D15*$Q$7+E15*$Q$8+F15*$Q$9 -> 1105.3792 | K15: =(J15/$J$2)-1 -> -0.067472689
A16: 44312 | B16: 1977.5 | C16: 1788.6349 | D16: 1413 | E16: 634.70001 | F16: 1330.05 | H16: =(B16*0.3+C16*'Price weighted Portfolio'!$B$22+'2.b Portfolios Daily Value'!D16*'Price weighted Portfolio'!$B$23+'2.b Portfolios Daily Value'!E16*'Price weighted Portfolio'!$B$24+'2.b Portfolios Daily Value'!F16*'Price weighted Portfolio'!$B$25) -> 1709.508 | I16: =(H16/$H$2)-1 -> -0.054029087 | J16: =B16*$Q$10+C16*$Q$6+D16*$Q$7+E16*$Q$8+F16*$Q$9 -> 1109.6978 | K16: =(J16/$J$2)-1 -> -0.063829393
A17: 44313 | B17: 2014.8 | C17: 1835.5233 | D17: 1407.25 | E17: 639.25 | F17: 1339 | H17: =(B17*0.3+C17*'Price weighted Portfolio'!$B$22+'2.b Portfolios Daily Value'!D17*'Price weighted Portfolio'!$B$23+'2.b Portfolios Daily Value'!E17*'Price weighted Portfolio'!$B$24+'2.b Portfolios Daily Value'!F17*'Price weighted Portfolio'!$B$25) -> 1741.5279 | I17: =(H17/$H$2)-1 -> -0.036310584 | J17: =B17*$Q$10+C17*$Q$6+D17*$Q$7+E17*$Q$8+F17*$Q$9 -> 1125.1774 | K17: =(J17/$J$2)-1 -> -0.050770433
A18: 44314 | B18: 2051.1499 | C18: 1843.5072 | D18: 1436.25 | E18: 643.40002 | F18: 1384.85 | H18: =(B18*0.3+C18*'Price weighted Portfolio'!$B$22+'2.b Portfolios Daily Value'!D18*'Price weighted Portfolio'!$B$23+'2.b Portfolios Daily Value'!E18*'Price weighted Portfolio'!$B$24+'2.b Portfolios Daily Value'!F18*'Price weighted Portfolio'!$B$25) -> 1764.5301 | I18: =(H18/$H$2)-1 -> -0.023582151 | J18: =B18*$Q$10+C18*$Q$6+D18*$Q$7+E18*$Q$8+F18*$Q$9 -> 1147.3799 | K18: =(J18/$J$2)-1 -> -0.032039773
A19: 44315 | B19: 2073.95 | C19: 1868.1975 | D19: 1486.2 | E19: 644.5 | F19: 1383.95 | H19: =(B19*0.3+C19*'Price weighted Portfolio'!$B$22+'2.b Portfolios Daily Value'!D19*'Price weighted Portfolio'!$B$23+'2.b Portfolios Daily Value'!E19*'Price weighted Portfolio'!$B$24+'2.b Portfolios Daily Value'!F19*'Price weighted Portfolio'!$B$25) -> 1786.0901 | I19: =(H19/$H$2)-1 -> -0.01165172 | J19: =B19*$Q$10+C19*$Q$6+D19*$Q$7+E19*$Q$8+F19*$Q$9 -> 1160.0242 | K19: =(J19/$J$2)-1 -> -0.021372732
A20: 44316 | B20: 2228.75 | C20: 1840.9229 | D20: 1445 | E20: 654.45001 | F20: 1350 | H20: =(B20*0.3+C20*'Price weighted Portfolio'!$B$22+'2.b Portfolios Daily Value'!D20*'Price weighted Portfolio'!$B$23+'2.b Portfolios Daily Value'!E20*'Price weighted Portfolio'!$B$24+'2.b Portfolios Daily Value'!F20*'Price weighted Portfolio'!$B$25) -> 1814.4894 | I20: =(H20/$H$2)-1 -> 0.0040632707 | J20: =B20*$Q$10+C20*$Q$6+D20*$Q$7+E20*$Q$8+F20*$Q$9 -> 1196.1878 | K20: =(J20/$J$2)-1 -> 0.0091358621
A21: 44319 | B21: 2282.8999 | C21: 1808.2025 | D21: 1393 | E21: 659.20001 | F21: 1325.5 | H21: =(B21*0.3+C21*'Price weighted Portfolio'!$B$22+'2.b Portfolios Daily Value'!D21*'Price weighted Portfolio'!$B$23+'2.b Portfolios Daily Value'!E21*'Price weighted Portfolio'!$B$24+'2.b Portfolios Daily Value'!F21*'Price weighted Portfolio'!$B$25) -> 1810.0148 | I21: =(H21/$H$2)-1 -> 0.0015872176 | J21: =B21*$Q$10+C21*$Q$6+D21*$Q$7+E21*$Q$8+F21*$Q$9 -> 1202.0704 | K21: =(J21/$J$2)-1 -> 0.014098598
A22: 44320 | B22: 2281.55 | C22: 1769.0211 | D22: 1409.95 | E22: 645.15002 | F22: 1350 | H22: =(B22*0.3+C22*'Price weighted Portfolio'!$B$22+'2.b Portfolios Daily Value'!D22*'Price weighted Portfolio'!$B$23+'2.b Portfolios Daily Value'!E22*'Price weighted Portfolio'!$B$24+'2.b Portfolios Daily Value'!F22*'Price weighted Portfolio'!$B$25) -> 1795.9989 | I22: =(H22/$H$2)-1 -> -0.0061686136 | J22: =B22*$Q$10+C22*$Q$6+D22*$Q$7+E22*$Q$8+F22*$Q$9 -> 1203.7927 | K22: =(J22/$J$2)-1 -> 0.015551575
A23: 44321 | B23: 2320.7 | C23: 1772.2517 | D23: 1401 | E23: 683.40002 | F23: 1342.2 | H23: =(B23*0.3+C23*'Price weighted Portfolio'!$B$22+'2.b Portfolios Daily Value'!D23*'Price weighted Portfolio'!$B$23+'2.b Portfolios Daily Value'!E23*'Price weighted Portfolio'!$B$24+'2.b Portfolios Daily Value'!F23*'Price weighted Portfolio'!$B$25) -> 1812.016 | I23: =(H23/$H$2)-1 -> 0.0026945641 | J23: =B23*$Q$10+C23*$Q$6+D23*$Q$7+E23*$Q$8+F23*$Q$9 -> 1216.8735 | K23: =(J23/$J$2)-1 -> 0.026586851
... A741: 45379 | B741: 3337.05 | C741: 2971.7 | D741: 1440.7 | E741: 1620.55 | F741: 3706.55 | H741: =(B741*0.3+C741*'Price weighted Portfolio'!$B$22+'2.b Portfolios Daily Value'!D741*'Price weighted Portfolio'!$B$23+'2.b Portfolios Daily Value'!E741*'Price weighted Portfolio'!$B$24+'2.b Portfolios Daily Value'!F741*'Price weighted Portfolio'!$B$25) -> 3032.6114 | I741: =(H741/$H$2)-1 -> 0.67812154 | J741: =B741*$Q$10+C741*$Q$6+D741*$Q$7+E741*$Q$8+F741*$Q$9 -> 2087.0176 | K741: =(J741/$J$2)-1 -> 0.76066355

Sheet Price weighted Portfolio
E1: Date | F1: BASF | G1: RELIANCE | H1: HDFCBANK | I1: SUNPHARMA | J1: LT | K1: PORTFOLIO VALUE | L1: Daily Return
E2: 44287 | F2: 2136.8999 | G2: 1866.1669 | H2: 1499.4 | I2: 610.75 | J2: 1432 | K2: =($B$22*$F2)+($B$23*$G2)+($B$24*$H2)+($B$25*$I2)+($B$26*$J2) -> 1671.0903
E3: 44291 | F3: 2034.95 | G3: 1839.1692 | H3: 1480 | I3: 608.79999 | J3: 1439 | K3: =($B$22*$F3)+($B$23*$G3)+($B$24*$H3)+($B$25*$I3)+($B$26*$J3) -> 1625.1146 | L3: =(K3/K2)-1 -> -0.027512416
A4: Stock | B4: Price | E4: 44292 | F4: 2101.6499 | G4: 1831.5083 | H4: 1460 | I4: 620.45001 | J4: 1405.9 | K4: =($B$22*$F4)+($B$23*$G4)+($B$24*$H4)+($B$25*$I4)+($B$26*$J4) -> 1643.2518 | L4: =(K4/K3)-1 -> 0.011160585 | O4: 2021-2024 | P4: 2021-2022 | Q4: 2022-2023 | R4: 2023-2024
A5: BASF | B5: 5962 | E5: 44293 | F5: 2094.95 | G5: 1848.6299 | H5: 1439.3 | I5: 621.04999 | J5: 1402 | K5: =($B$22*$F5)+($B$23*$G5)+($B$24*$H5)+($B$25*$I5)+($B$26*$J5) -> 1638.5176 | L5: =(K5/K4)-1 -> -0.0028810113 | N5: Average Daily Return: | O5: =AVERAGE(L3:L741) -> 0.00084952689 | P5: =AVERAGE(L3:L250) -> 0.0012644237 | Q5: =AVERAGE(L251:L498) -> -0.00035106347 | R5: =AVERAGE(L499:L741) -> 0.001651387
A6: RELIANCE | B6: 1237.4 | E6: 44294 | F6: 2094.6499 | G6: 1850.9374 | H6: 1453 | I6: 614.25 | J6: 1410 | K6: =($B$22*$F6)+($B$23*$G6)+($B$24*$H6)+($B$25*$I6)+($B$26*$J6) -> 1641.392 | L6: =(K6/K5)-1 -> 0.0017542352 | N6: Annual Daily Return: | O6: =((1+O5)^252)-1 -> 0.23861014 | P6: =((1+P5)^248)-1 -> 0.36803992 | Q6: =((1+Q5)^248)-1 -> -0.083395343 | R6: =((1+R5)^243)-1 -> 0.49325166
A7: HDFCBANK | B7: 1736 | E7: 44295 | F7: 2068.8 | G7: 1829.4315 | H7: 1426 | I7: 636.75 | J7: 1414 | K7: =($B$22*$F7)+($B$23*$G7)+($B$24*$H7)+($B$25*$I7)+($B$26*$J7) -> 1629.1812 | L7: =(K7/K6)-1 -> -0.0074392405
A8: SUNPHARMA | B8: 1774 | E8: 44298 | F8: 1940.4 | G8: 1763.9908 | H8: 1393 | I8: 619.34998 | J8: 1393.95 | K8: =($B$22*$F8)+($B$23*$G8)+($B$24*$H8)+($B$25*$I8)+($B$26*$J8) -> 1558.5047 | L8: =(K8/K7)-1 -> -0.043381628 | N8: Daily Std Dev: | O8: =_xlfn.STDEV.S(L3:L741) -> 0.012692917 | P8: =_xlfn.STDEV.S(L3:L250) -> 0.016458496 | Q8: =_xlfn.STDEV.S(L251:L498) -> 0.012108357 | R8: =_xlfn.STDEV.S(L499:L741) -> 0.0079309425
A9: LT | B9: 3511 | E9: 44299 | F9: 2118.3501 | G9: 1783.0508 | H9: 1368 | I9: 627.34998 | J9: 1347.25 | K9: =($B$22*$F9)+($B$23*$G9)+($B$24*$H9)+($B$25*$I9)+($B$26*$J9) -> 1621.1859 | L9: =(K9/K8)-1 -> 0.0402188 | N9: Annual Std Dev: | O9: =O8*SQRT(252) -> 0.20149381 | P9: =P8*SQRT(248) -> 0.25918866 | Q9: =Q8*SQRT(248) -> 0.1906826 | R9: =R8*SQRT(243) -> 0.12363116
E10: 44301 | F10: 2083.5 | G10: 1794.5883 | H10: 1405 | I10: 633.25 | J10: 1378.95 | K10: =($B$22*$F10)+($B$23*$G10)+($B$24*$H10)+($B$25*$I10)+($B$26*$J10) -> 1620.6583 | L10: =(K10/K9)-1 -> -0.00032543895
A11: Sum of all the stocks is calculated as: | E11: 44302 | F11: 2099.8999 | G11: 1783.3276 | H11: 1434.95 | I11: 646.04999 | J11: 1360.5 | K11: =($B$22*$F11)+($B$23*$G11)+($B$24*$H11)+($B$25*$I11)+($B$26*$J11) -> 1627.252 | L11: =(K11/K10)-1 -> 0.0040685227
A12: Sum of all the Stocks | B12: =SUM(B5:B9) -> 14220.4 | E12: 44305 | F12: 2027.6 | G12: 1755.2684 | H12: 1390 | I12: 640.65002 | J12: 1340 | K12: =($B$22*$F12)+($B$23*$G12)+($B$24*$H12)+($B$25*$I12)+($B$26*$J12) -> 1583.2757 | L12: =(K12/K11)-1 -> -0.027024895
E13: 44306 | F13: 2020.15 | G13: 1754.7609 | H13: 1425 | I13: 645.15002 | J13: 1320 | K13: =($B$22*$F13)+($B$23*$G13)+($B$24*$H13)+($B$25*$I13)+($B$26*$J13) -> 1580.0042 | L13: =(K13/K12)-1 -> -0.0020662698 | N13: 2021-2024
A14: Number of stocks | B14: 5 | E14: 44308 | F14: 2033 | G14: 1759.6066 | H14: 1380 | I14: 639.95001 | J14: 1310 | K14: =($B$22*$F14)+($B$23*$G14)+($B$24*$H14)+($B$25*$I14)+($B$26*$J14) -> 1577.2021 | L14: =(K14/K13)-1 -> -0.0017734856 | N14: Variable | O14: Abbreviation | P14: Portfolio | Q14: CAPM Model Used (Assumption)
E15: 44309 | F15: 1969.65 | G15: 1757.7145 | H15: 1409 | I15: 637.95001 | J15: 1330 | K15: =($B$22*$F15)+($B$23*$G15)+($B$24*$H15)+($B$25*$I15)+($B$26*$J15) -> 1558.7063 | L15: =(K15/K14)-1 -> -0.011726976 | N15: Risk Free Rate | O15: Rf | P15: 0.05
A16: Price Index is calculated using formula given below | E16: 44312 | F16: 1977.5 | G16: 1788.6349 | H16: 1413 | I16: 634.70001 | J16: 1330.05 | K16: =($B$22*$F16)+($B$23*$G16)+($B$24*$H16)+($B$25*$I16)+($B$26*$J16) -> 1564.7832 | L16: =(K16/K15)-1 -> 0.0038987156 | N16: Annual Return | O16: Rp | P16: =O6 -> 0.23861014
A17: Price Index = Sum of all the prices of Stocks which are part of Index / Number of Stocks in the Index | E17: 44313 | F17: 2014.8 | G17: 1835.5233 | H17: 1407.25 | I17: 639.25 | J17: 1339 | K17: =($B$22*$F17)+($B$23*$G17)+($B$24*$H17)+($B$25*$I17)+($B$26*$J17) -> 1586.577 | L17: =(K17/K16)-1 -> 0.013927637 | N17: Annual Standard Deviation | O17: σ | P17: 0.2015
E18: 44314 | F18: 2051.1499 | G18: 1843.5072 | H18: 1436.25 | I18: 643.40002 | J18: 1384.85 | K18: =($B$22*$F18)+($B$23*$G18)+($B$24*$H18)+($B$25*$I18)+($B$26*$J18) -> 1617.8899 | L18: =(K18/K17)-1 -> 0.01973616
A19: Price Index | B19: =B12/B14 -> 2844.08 | E19: 44315 | F19: 2073.95 | G19: 1868.1975 | H19: 1486.2 | I19: 644.5 | J19: 1383.95 | K19: =($B$22*$F19)+($B$23*$G19)+($B$24*$H19)+($B$25*$I19)+($B$26*$J19) -> 1635.6102 | L19: =(K19/K18)-1 -> 0.010952741 | N19: Sharpe Ratio | P19: =(P16-P15)/P17 -> 0.93603046
E20: 44316 | F20: 2228.75 | G20: 1840.9229 | H20: 1445 | I20: 654.45001 | J20: 1350 | K20: =($B$22*$F20)+($B$23*$G20)+($B$24*$H20)+($B$25*$I20)+($B$26*$J20) -> 1685.9673 | L20: =(K20/K19)-1 -> 0.030787961
A21: Stock | B21: Weights | E21: 44319 | F21: 2282.8999 | G21: 1808.2025 | H21: 1393 | I21: 659.20001 | J21: 1325.5 | K21: =($B$22*$F21)+($B$23*$G21)+($B$24*$H21)+($B$25*$I21)+($B$26*$J21) -> 1694.0183 | L21: =(K21/K20)-1 -> 0.0047753056 | N21: *Sharpe Ratio = (Rp - Rf) / σ
A22: BASF | B22: =$B5/$B$12 -> 0.41925684 | E22: 44320 | F22: 2281.55 | G22: 1769.0211 | H22: 1409.95 | I22: 645.15002 | J22: 1350 | K22: =($B$22*$F22)+($B$23*$G22)+($B$24*$H22)+($B$25*$I22)+($B$26*$J22) -> 1696.4085 | L22: =(K22/K21)-1 -> 0.0014109419 | N22: 2021-2022
A23: RELIANCE | B23: =$B6/$B$12 -> 0.087015836 | E23: 44321 | F23: 2320.7 | G23: 1772.2517 | H23: 1401 | I23: 683.40002 | J23: 1342.2 | K23: =($B$22*$F23)+($B$23*$G23)+($B$24*$H23)+($B$25*$I23)+($B$26*$J23) -> 1714.8568 | L23: =(K23/K22)-1 -> 0.010874894 | N23: Variable | O23: Abbreviation | P23: Portfolio | Q23: CAPM Model Used (Assumption)
A24: HDFCBANK | B24: =$B7/$B$12 -> 0.12207814 | E24: 44322 | F24: 2294.8999 | G24: 1782.3124 | H24: 1407.6 | I24: 679.40002 | J24: 1344 | K24: =($B$22*$F24)+($B$23*$G24)+($B$24*$H24)+($B$25*$I24)+($B$26*$J24) -> 1705.6665 | L24: =(K24/K23)-1 -> -0.0053592046 | N24: Risk Free Rate | O24: Rf | P24: 0.05
A25: SUNPHARMA | B25: =$B8/$B$12 -> 0.12475036 | E25: 44323 | F25: 2451.7 | G25: 1783.0046 | H25: 1412.95 | I25: 679.45001 | J25: 1347 | K25: =($B$22*$F25)+($B$23*$G25)+($B$24*$H25)+($B$25*$I25)+($B$26*$J25) -> 1772.8663 | L25: =(K25/K24)-1 -> 0.039397959 | N25: Annual Return | O25: Rp | P25: 0.36804
A26: LT | B26: =$B9/$B$12 -> 0.24689882 | E26: 44326 | F26: 2480.45 | G26: 1777.882 | H26: 1427 | I26: 698.20001 | J26: 1347 | K26: =($B$22*$F26)+($B$23*$G26)+($B$24*$H26)+($B$25*$I26)+($B$26*$J26) -> 1788.5284 | L26: =(K26/K25)-1 -> 0.0088343679 | N26: Annual Standard Deviation | O26: σ | P26: =P9 -> 0.25918866
A27: Sum of Weights | B27: =SUM(B22:B26) -> 1 | E27: 44327 | F27: 2493.6001 | G27: 1784.2969 | H27: 1396 | I27: 708.09998 | J27: 1380 | K27: =($B$22*$F27)+($B$23*$G27)+($B$24*$H27)+($B$25*$I27)+($B$26*$J27) -> 1800.1982 | L27: =(K27/K26)-1 -> 0.0065247782
E28: 44328 | F28: 2409.6499 | G28: 1765.8368 | H28: 1399.75 | I28: 702.84998 | J28: 1380 | K28: =($B$22*$F28)+($B$23*$G28)+($B$24*$H28)+($B$25*$I28)+($B$26*$J28) -> 1763.198 | L28: =(K28/K27)-1 -> -0.020553382 | N28: Sharpe Ratio | P28: =((P25-P24)/P26) -> 1.2270598
E29: 44330 | F29: 2471.1499 | G29: 1788.1273 | H29: 1394.35 | I29: 691.45001 | J29: 1394 | K29: =($B$22*$F29)+($B$23*$G29)+($B$24*$H29)+($B$25*$I29)+($B$26*$J29) -> 1792.2971 | L29: =(K29/K28)-1 -> 0.016503611
E30: 44333 | F30: 2389.45 | G30: 1809.4025 | H30: 1395.15 | I30: 687.15002 | J30: 1433 | K30: =($B$22*$F30)+($B$23*$G30)+($B$24*$H30)+($B$25*$I30)+($B$26*$J30) -> 1769.0855 | L30: =(K30/K29)-1 -> -0.012950805 | N30: *Sharpe Ratio = (Rp - Rf) / σ
E31: 44334 | F31: 2497.55 | G31: 1834.8772 | H31: 1458.95 | I31: 690.79999 | J31: 1405 | K31: =($B$22*$F31)+($B$23*$G31)+($B$24*$H31)+($B$25*$I31)+($B$26*$J31) -> 1817.9546 | L31: =(K31/K30)-1 -> 0.027623965 | N31: 2022-2023
E32: 44335 | F32: 2452.8 | G32: 1843.2765 | H32: 1470.2 | I32: 703.40002 | J32: 1414 | K32: =($B$22*$F32)+($B$23*$G32)+($B$24*$H32)+($B$25*$I32)+($B$26*$J32) -> 1805.0911 | L32: =(K32/K31)-1 -> -0.0070758339 | N32: Variable | O32: Abbreviation | P32: Portfolio | Q32: CAPM Model Used (Assumption)
E33: 44336 | F33: 2465.95 | G33: 1832.5236 | H33: 1458.35 | I33: 686.84998 | J33: 1410.8 | K33: =($B$22*$F33)+($B$23*$G33)+($B$24*$H33)+($B$25*$I33)+($B$26*$J33) -> 1805.3673 | L33: =(K33/K32)-1 -> 0.00015301156 | N33: Risk Free Rate | O33: Rf | P33: 0.05
E34: 44337 | F34: 2443.55 | G34: 1848.353 | H34: 1443 | I34: 690.40002 | J34: 1415 | K34: =($B$22*$F34)+($B$23*$G34)+($B$24*$H34)+($B$25*$I34)+($B$26*$J34) -> 1796.9593 | L34: =(K34/K33)-1 -> -0.0046572029 | N34: Annual Return | O34: Rp | P34: -0.08339
E35: 44340 | F35: 2405.3501 | G35: 1832.7543 | H35: 1503.25 | I35: 690.95001 | J35: 1420 | K35: =($B$22*$F35)+($B$23*$G35)+($B$24*$H35)+($B$25*$I35)+($B$26*$J35) -> 1788.2447 | L35: =(K35/K34)-1 -> -0.0048496459 | N35: Annual Standard Deviation | O35: σ | P35: =Q9 -> 0.1906826
E36: 44341 | F36: 2403.5 | G36: 1811.9868 | H36: 1510.5 | I36: 696.09998 | J36: 1460 | K36: =($B$22*$F36)+($B$23*$G36)+($B$24*$H36)+($B$25*$I36)+($B$26*$J36) -> 1797.0654 | L36: =(K36/K35)-1 -> 0.004932611
E37: 44342 | F37: 2340.05 | G37: 1818.3555 | H37: 1480 | I37: 703.79999 | J37: 1458.9 | K37: =($B$22*$F37)+($B$23*$G37)+($B$24*$H37)+($B$25*$I37)+($B$26*$J37) -> 1767.9834 | L37: =(K37/K36)-1 -> -0.016183072 | N37: Sharpe Ratio | P37: =((P34-P33)/P35) -> -0.69953946
E38: 44343 | F38: 2374.05 | G38: 1823.9397 | H38: 1473.1 | I38: 699.5 | J38: 1475.95 | K38: =($B$22*$F38)+($B$23*$G38)+($B$24*$H38)+($B$25*$I38)+($B$26*$J38) -> 1785.5549 | L38: =(K38/K37)-1 -> 0.0099387183
E39: 44344 | F39: 2364.7 | G39: 1933.4998 | H39: 1490.9 | I39: 669.75 | J39: 1487.1 | K39: =($B$22*$F39)+($B$23*$G39)+($B$24*$H39)+($B$25*$I39)+($B$26*$J39) -> 1792.3828 | L39: =(K39/K38)-1 -> 0.0038240042 | N39: *Sharpe Ratio = (Rp - Rf) / σ
E40: 44347 | F40: 2424.3 | G40: 1993.9562 | H40: 1500 | I40: 668.29999 | J40: 1472.3 | K40: =($B$22*$F40)+($B$23*$G40)+($B$24*$H40)+($B$25*$I40)+($B$26*$J40) -> 1819.9072 | L40: =(K40/K39)-1 -> 0.015356289 | N40: 2023-2024
...

Sheet Equally weighted Portfolio 
A1: Let’s see some practical example and take some well know stocks from the market. | E1: Date | F1: BASF | G1: RELIANCE | H1: HDFCBANK | I1: SUNPHARMA | J1: LT | K1: PORTFOLIO VALUE | L1: Daily Return
E2: 44287 | F2: 2136.8999 | G2: 1866.1669 | H2: 1499.4 | I2: 610.75 | J2: 1432 | K2: =($B$22*$F2)+($B$23*$G2)+($B$24*$H2)+($B$25*$I2)+($B$26*$J2) -> 1509.0434
E3: 44291 | F3: 2034.95 | G3: 1839.1692 | H3: 1480 | I3: 608.79999 | J3: 1439 | K3: =($B$22*$F3)+($B$23*$G3)+($B$24*$H3)+($B$25*$I3)+($B$26*$J3) -> 1480.3838 | L3: =(K3/K2)-1 -> -0.018991856
A4: Stock | B4: Price | E4: 44292 | F4: 2101.6499 | G4: 1831.5083 | H4: 1460 | I4: 620.45001 | J4: 1405.9 | K4: =($B$22*$F4)+($B$23*$G4)+($B$24*$H4)+($B$25*$I4)+($B$26*$J4) -> 1483.9016 | L4: =(K4/K3)-1 -> 0.0023762906 | O4: 2021-2024 | P4: 2021-2022 | Q4: 2022-2023 | R4: 2023-2024
A5: BASF | B5: 5962 | E5: 44293 | F5: 2094.95 | G5: 1848.6299 | H5: 1439.3 | I5: 621.04999 | J5: 1402 | K5: =($B$22*$F5)+($B$23*$G5)+($B$24*$H5)+($B$25*$I5)+($B$26*$J5) -> 1481.186 | L5: =(K5/K4)-1 -> -0.00183009 | N5: Average Daily Return: | O5: =AVERAGE(L3:L741) -> 0.0007909382 | P5: =AVERAGE(L3:L250) -> 0.0010531305 | Q5: =AVERAGE(L251:L498) -> -0.00015285451 | R5: =AVERAGE(L499:L741) -> 0.0014865633
A6: RELIANCE | B6: 1237.4 | E6: 44294 | F6: 2094.6499 | G6: 1850.9374 | H6: 1453 | I6: 614.25 | J6: 1410 | K6: =($B$22*$F6)+($B$23*$G6)+($B$24*$H6)+($B$25*$I6)+($B$26*$J6) -> 1484.5675 | L6: =(K6/K5)-1 -> 0.0022829556 | N6: Annual Daily Return: | O6: =((1+O5)^252)-1 -> 0.22047197 | P6: =((1+P5)^248)-1 -> 0.29827821 | Q6: =((1+Q5)^243)-1 -> -0.036465019 | R6: =((1+R5)^243)-1 -> 0.43471562
A7: HDFCBANK | B7: 1736 | E7: 44295 | F7: 2068.8 | G7: 1829.4315 | H7: 1426 | I7: 636.75 | J7: 1414 | K7: =($B$22*$F7)+($B$23*$G7)+($B$24*$H7)+($B$25*$I7)+($B$26*$J7) -> 1474.9963 | L7: =(K7/K6)-1 -> -0.0064470916
A8: SUNPHARMA | B8: 1774 | E8: 44298 | F8: 1940.4 | G8: 1763.9908 | H8: 1393 | I8: 619.34998 | J8: 1393.95 | K8: =($B$22*$F8)+($B$23*$G8)+($B$24*$H8)+($B$25*$I8)+($B$26*$J8) -> 1422.1382 | L8: =(K8/K7)-1 -> -0.035836126 | N8: Daily Std Dev: | O8: =_xlfn.STDEV.S(L3:L741) -> 0.0096600652 | P8: =_xlfn.STDEV.S(L3:L250) -> 0.011901354 | Q8: =_xlfn.STDEV.S(L251:L498) -> 0.0096480284 | R8: =_xlfn.STDEV.S(L499:L741) -> 0.0065979
A9: LT | B9: 3511 | E9: 44299 | F9: 2118.3501 | G9: 1783.0508 | H9: 1368 | I9: 627.34998 | J9: 1347.25 | K9: =($B$22*$F9)+($B$23*$G9)+($B$24*$H9)+($B$25*$I9)+($B$26*$J9) -> 1448.8002 | L9: =(K9/K8)-1 -> 0.018747835 | N9: Annual Std Dev: | O9: =O8*SQRT(252) -> 0.15334878 | P9: =P8*SQRT(248) -> 0.18742271 | Q9: =Q8*SQRT(248) -> 0.1519373 | R9: =R8*SQRT(243) -> 0.10285108
E10: 44301 | F10: 2083.5 | G10: 1794.5883 | H10: 1405 | I10: 633.25 | J10: 1378.95 | K10: =($B$22*$F10)+($B$23*$G10)+($B$24*$H10)+($B$25*$I10)+($B$26*$J10) -> 1459.0576 | L10: =(K10/K9)-1 -> 0.0070799761
A11: Sum of all the stocks is calculated as: | E11: 44302 | F11: 2099.8999 | G11: 1783.3276 | H11: 1434.95 | I11: 646.04999 | J11: 1360.5 | K11: =($B$22*$F11)+($B$23*$G11)+($B$24*$H11)+($B$25*$I11)+($B$26*$J11) -> 1464.9455 | L11: =(K11/K10)-1 -> 0.0040353814
A12: Sum of all the Stocks | B12: =SUM(B5:B9) -> 14220.4 | E12: 44305 | F12: 2027.6 | G12: 1755.2684 | H12: 1390 | I12: 640.65002 | J12: 1340 | K12: =($B$22*$F12)+($B$23*$G12)+($B$24*$H12)+($B$25*$I12)+($B$26*$J12) -> 1430.7037 | L12: =(K12/K11)-1 -> -0.023374118
E13: 44306 | F13: 2020.15 | G13: 1754.7609 | H13: 1425 | I13: 645.15002 | J13: 1320 | K13: =($B$22*$F13)+($B$23*$G13)+($B$24*$H13)+($B$25*$I13)+($B$26*$J13) -> 1433.0122 | L13: =(K13/K12)-1 -> 0.0016135387 | N13: 2021-2024
A14: Number of stocks | B14: 5 | E14: 44308 | F14: 2033 | G14: 1759.6066 | H14: 1380 | I14: 639.95001 | J14: 1310 | K14: =($B$22*$F14)+($B$23*$G14)+($B$24*$H14)+($B$25*$I14)+($B$26*$J14) -> 1424.5113 | L14: =(K14/K13)-1 -> -0.0059321663 | N14: Variable | O14: Abbreviation | P14: Portfolio | Q14: CAPM Model Used (Assumption)
E15: 44309 | F15: 1969.65 | G15: 1757.7145 | H15: 1409 | I15: 637.95001 | J15: 1330 | K15: =($B$22*$F15)+($B$23*$G15)+($B$24*$H15)+($B$25*$I15)+($B$26*$J15) -> 1420.8629 | L15: =(K15/K14)-1 -> -0.0025611681 | N15: Risk Free Rate | O15: Rf | P15: 0.05
E16: 44312 | F16: 1977.5 | G16: 1788.6349 | H16: 1413 | I16: 634.70001 | J16: 1330.05 | K16: =($B$22*$F16)+($B$23*$G16)+($B$24*$H16)+($B$25*$I16)+($B$26*$J16) -> 1428.777 | L16: =(K16/K15)-1 -> 0.005569916 | N16: Annual Return | O16: Rp | P16: 0.2205
E17: 44313 | F17: 2014.8 | G17: 1835.5233 | H17: 1407.25 | I17: 639.25 | J17: 1339 | K17: =($B$22*$F17)+($B$23*$G17)+($B$24*$H17)+($B$25*$I17)+($B$26*$J17) -> 1447.1647 | L17: =(K17/K16)-1 -> 0.012869526 | N17: Annual Standard Deviation | O17: σ | P17: 0.1533
E18: 44314 | F18: 2051.1499 | G18: 1843.5072 | H18: 1436.25 | I18: 643.40002 | J18: 1384.85 | K18: =($B$22*$F18)+($B$23*$G18)+($B$24*$H18)+($B$25*$I18)+($B$26*$J18) -> 1471.8314 | L18: =(K18/K17)-1 -> 0.01704488
A19: Price Index | B19: =B12/B14 -> 2844.08 | E19: 44315 | F19: 2073.95 | G19: 1868.1975 | H19: 1486.2 | I19: 644.5 | J19: 1383.95 | K19: =($B$22*$F19)+($B$23*$G19)+($B$24*$H19)+($B$25*$I19)+($B$26*$J19) -> 1491.3595 | L19: =(K19/K18)-1 -> 0.013267859 | N19: Sharpe Ratio | P19: =(P16-P15)/P17 -> 1.1121983
E20: 44316 | F20: 2228.75 | G20: 1840.9229 | H20: 1445 | I20: 654.45001 | J20: 1350 | K20: =($B$22*$F20)+($B$23*$G20)+($B$24*$H20)+($B$25*$I20)+($B$26*$J20) -> 1503.8246 | L20: =(K20/K19)-1 -> 0.008358213
A21: Stock | B21: Weights | E21: 44319 | F21: 2282.8999 | G21: 1808.2025 | H21: 1393 | I21: 659.20001 | J21: 1325.5 | K21: =($B$22*$F21)+($B$23*$G21)+($B$24*$H21)+($B$25*$I21)+($B$26*$J21) -> 1493.7605 | L21: =(K21/K20)-1 -> -0.0066923278 | N21: *Sharpe Ratio = (Rp - Rf) / σ
A22: BASF | B22: =0.2 -> 0.2 | E22: 44320 | F22: 2281.55 | G22: 1769.0211 | H22: 1409.95 | I22: 645.15002 | J22: 1350 | K22: =($B$22*$F22)+($B$23*$G22)+($B$24*$H22)+($B$25*$I22)+($B$26*$J22) -> 1491.1342 | L22: =(K22/K21)-1 -> -0.0017581516 | N22: 2021-2022
A23: RELIANCE | B23: =0.2 -> 0.2 | E23: 44321 | F23: 2320.7 | G23: 1772.2517 | H23: 1401 | I23: 683.40002 | J23: 1342.2 | K23: =($B$22*$F23)+($B$23*$G23)+($B$24*$H23)+($B$25*$I23)+($B$26*$J23) -> 1503.9103 | L23: =(K23/K22)-1 -> 0.0085680406 | N23: Variable | O23: Abbreviation | P23: Portfolio | Q23: CAPM Model Used (Assumption)
A24: HDFCBANK | B24: =0.2 -> 0.2 | E24: 44322 | F24: 2294.8999 | G24: 1782.3124 | H24: 1407.6 | I24: 679.40002 | J24: 1344 | K24: =($B$22*$F24)+($B$23*$G24)+($B$24*$H24)+($B$25*$I24)+($B$26*$J24) -> 1501.6425 | L24: =(K24/K23)-1 -> -0.0015079829 | N24: Risk Free Rate | O24: Rf | P24: 0.05
A25: SUNPHARMA | B25: =0.2 -> 0.2 | E25: 44323 | F25: 2451.7 | G25: 1783.0046 | H25: 1412.95 | I25: 679.45001 | J25: 1347 | K25: =($B$22*$F25)+($B$23*$G25)+($B$24*$H25)+($B$25*$I25)+($B$26*$J25) -> 1534.8209 | L25: =(K25/K24)-1 -> 0.022094777 | N25: Annual Return | O25: Rp | P25: 0.2983
A26: LT | B26: =0.2 -> 0.2 | E26: 44326 | F26: 2480.45 | G26: 1777.882 | H26: 1427 | I26: 698.20001 | J26: 1347 | K26: =($B$22*$F26)+($B$23*$G26)+($B$24*$H26)+($B$25*$I26)+($B$26*$J26) -> 1546.1064 | L26: =(K26/K25)-1 -> 0.0073529579 | N26: Annual Standard Deviation | O26: σ | P26: 0.1874
A27: Sum of Weights | B27: =SUM(B22:B26) -> 1 | E27: 44327 | F27: 2493.6001 | G27: 1784.2969 | H27: 1396 | I27: 708.09998 | J27: 1380 | K27: =($B$22*$F27)+($B$23*$G27)+($B$24*$H27)+($B$25*$I27)+($B$26*$J27) -> 1552.3994 | L27: =(K27/K26)-1 -> 0.0040702281
E28: 44328 | F28: 2409.6499 | G28: 1765.8368 | H28: 1399.75 | I28: 702.84998 | J28: 1380 | K28: =($B$22*$F28)+($B$23*$G28)+($B$24*$H28)+($B$25*$I28)+($B$26*$J28) -> 1531.6173 | L28: =(K28/K27)-1 -> -0.013387055 | N28: Sharpe Ratio | P28: =((P25-P24)/P26) -> 1.3249733
E29: 44330 | F29: 2471.1499 | G29: 1788.1273 | H29: 1394.35 | I29: 691.45001 | J29: 1394 | K29: =($B$22*$F29)+($B$23*$G29)+($B$24*$H29)+($B$25*$I29)+($B$26*$J29) -> 1547.8154 | L29: =(K29/K28)-1 -> 0.010575819
E30: 44333 | F30: 2389.45 | G30: 1809.4025 | H30: 1395.15 | I30: 687.15002 | J30: 1433 | K30: =($B$22*$F30)+($B$23*$G30)+($B$24*$H30)+($B$25*$I30)+($B$26*$J30) -> 1542.8305 | L30: =(K30/K29)-1 -> -0.0032206351 | N30: *Sharpe Ratio = (Rp - Rf) / σ
E31: 44334 | F31: 2497.55 | G31: 1834.8772 | H31: 1458.95 | I31: 690.79999 | J31: 1405 | K31: =($B$22*$F31)+($B$23*$G31)+($B$24*$H31)+($B$25*$I31)+($B$26*$J31) -> 1577.4354 | L31: =(K31/K30)-1 -> 0.022429518 | N31: 2022-2023
E32: 44335 | F32: 2452.8 | G32: 1843.2765 | H32: 1470.2 | I32: 703.40002 | J32: 1414 | K32: =($B$22*$F32)+($B$23*$G32)+($B$24*$H32)+($B$25*$I32)+($B$26*$J32) -> 1576.7353 | L32: =(K32/K31)-1 -> -0.00044384346 | N32: Variable | O32: Abbreviation | P32: Portfolio | Q32: CAPM Model Used (Assumption)
E33: 44336 | F33: 2465.95 | G33: 1832.5236 | H33: 1458.35 | I33: 686.84998 | J33: 1410.8 | K33: =($B$22*$F33)+($B$23*$G33)+($B$24*$H33)+($B$25*$I33)+($B$26*$J33) -> 1570.8947 | L33: =(K33/K32)-1 -> -0.0037042363 | N33: Risk Free Rate | O33: Rf | P33: 0.05
E34: 44337 | F34: 2443.55 | G34: 1848.353 | H34: 1443 | I34: 690.40002 | J34: 1415 | K34: =($B$22*$F34)+($B$23*$G34)+($B$24*$H34)+($B$25*$I34)+($B$26*$J34) -> 1568.0606 | L34: =(K34/K33)-1 -> -0.0018041199 | N34: Annual Return | O34: Rp | P34: -0.0365
E35: 44340 | F35: 2405.3501 | G35: 1832.7543 | H35: 1503.25 | I35: 690.95001 | J35: 1420 | K35: =($B$22*$F35)+($B$23*$G35)+($B$24*$H35)+($B$25*$I35)+($B$26*$J35) -> 1570.4609 | L35: =(K35/K34)-1 -> 0.0015307166 | N35: Annual Standard Deviation | O35: σ | P35: 0.1519
E36: 44341 | F36: 2403.5 | G36: 1811.9868 | H36: 1510.5 | I36: 696.09998 | J36: 1460 | K36: =($B$22*$F36)+($B$23*$G36)+($B$24*$H36)+($B$25*$I36)+($B$26*$J36) -> 1576.4174 | L36: =(K36/K35)-1 -> 0.0037928242
E37: 44342 | F37: 2340.05 | G37: 1818.3555 | H37: 1480 | I37: 703.79999 | J37: 1458.9 | K37: =($B$22*$F37)+($B$23*$G37)+($B$24*$H37)+($B$25*$I37)+($B$26*$J37) -> 1560.2211 | L37: =(K37/K36)-1 -> -0.010274089 | N37: Sharpe Ratio | P37: =((P34-P33)/P35) -> -0.56945359
E38: 44343 | F38: 2374.05 | G38: 1823.9397 | H38: 1473.1 | I38: 699.5 | J38: 1475.95 | K38: =($B$22*$F38)+($B$23*$G38)+($B$24*$H38)+($B$25*$I38)+($B$26*$J38) -> 1569.3079 | L38: =(K38/K37)-1 -> 0.0058240647
E39: 44344 | F39: 2364.7 | G39: 1933.4998 | H39: 1490.9 | I39: 669.75 | J39: 1487.1 | K39: =($B$22*$F39)+($B$23*$G39)+($B$24*$H39)+($B$25*$I39)+($B$26*$J39) -> 1589.1899 | L39: =(K39/K38)-1 -> 0.012669283 | N39: *Sharpe Ratio = (Rp - Rf) / σ
E40: 44347 | F40: 2424.3 | G40: 1993.9562 | H40: 1500 | I40: 668.29999 | J40: 1472.3 | K40: =($B$22*$F40)+($B$23*$G40)+($B$24*$H40)+($B$25*$I40)+($B$26*$J40) -> 1611.7713 | L40: =(K40/K39)-1 -> 0.014209322 | N40: 2023-2024
...

Sheet Sheet 3
A1: Date | B1: BASF | C1: RELIANCE | D1: HDFCBANK | E1: SUNPHARMA | F1: LT | G1: BASF Daily Returns | H1: RELIANCE Daily Returns | I1: HDFC BANK Daily Returns | J1: SUNPHARMA Daily Returns | K1: LT Daily Returns
A2: 44287 | B2: 2136.8999 | C2: 1866.1669 | D2: 1499.4 | E2: 610.75 | F2: 1432
A3: 44291 | B3: 2034.95 | C3: 1839.1692 | D3: 1480 | E3: 608.8 | F3: 1439 | G3: =(B3-B2)/B2 -> -0.047709254 | H3: =(C3-C2)/C2 -> -0.014466927 | I3: =(D3-D2)/D2 -> -0.012938509 | J3: =(E3-E2)/E2 -> -0.0031927957 | K3: =(F3-F2)/F2 -> 0.0048882682
A4: 44292 | B4: 2101.6499 | C4: 1831.5083 | D4: 1460 | E4: 620.45 | F4: 1405.9 | G4: =(B4-B3)/B3 -> 0.032777169 | H4: =(C4-C3)/C3 -> -0.0041654134 | I4: =(D4-D3)/D3 -> -0.013513514 | J4: =(E4-E3)/E3 -> 0.019136005 | K4: =(F4-F3)/F3 -> -0.023002085
A5: 44293 | B5: 2094.95 | C5: 1848.6299 | D5: 1439.3 | E5: 621.05 | F5: 1402 | G5: =(B5-B4)/B4 -> -0.0031879239 | H5: =(C5-C4)/C4 -> 0.0093483606 | I5: =(D5-D4)/D4 -> -0.014178082 | J5: =(E5-E4)/E4 -> 0.00096704005 | K5: =(F5-F4)/F4 -> -0.0027740238
A6: 44294 | B6: 2094.6499 | C6: 1850.9374 | D6: 1453 | E6: 614.25 | F6: 1410 | G6: =(B6-B5)/B5 -> -0.00014324924 | H6: =(C6-C5)/C5 -> 0.0012482217 | I6: =(D6-D5)/D5 -> 0.0095185159 | J6: =(E6-E5)/E5 -> -0.010949199 | K6: =(F6-F5)/F5 -> 0.0057061341
A7: 44295 | B7: 2068.8 | C7: 1829.4315 | D7: 1426 | E7: 636.75 | F7: 1414 | G7: =(B7-B6)/B6 -> -0.012340917 | H7: =(C7-C6)/C6 -> -0.011618923 | I7: =(D7-D6)/D6 -> -0.018582244 | J7: =(E7-E6)/E6 -> 0.036630037 | K7: =(F7-F6)/F6 -> 0.0028368794
A8: 44298 | B8: 1940.4 | C8: 1763.9908 | D8: 1393 | E8: 619.35 | F8: 1393.95 | G8: =(B8-B7)/B7 -> -0.062064965 | H8: =(C8-C7)/C7 -> -0.035771058 | I8: =(D8-D7)/D7 -> -0.023141655 | J8: =(E8-E7)/E7 -> -0.027326266 | K8: =(F8-F7)/F7 -> -0.014179632
A9: 44299 | B9: 2118.3501 | C9: 1783.0508 | D9: 1368 | E9: 627.35 | F9: 1347.25 | G9: =(B9-B8)/B8 -> 0.091707947 | H9: =(C9-C8)/C8 -> 0.010805045 | I9: =(D9-D8)/D8 -> -0.017946877 | J9: =(E9-E8)/E8 -> 0.012916768 | K9: =(F9-F8)/F8 -> -0.033501919
A10: 44301 | B10: 2083.5 | C10: 1794.5883 | D10: 1405 | E10: 633.25 | F10: 1378.95 | G10: =(B10-B9)/B9 -> -0.01645153 | H10: =(C10-C9)/C9 -> 0.0064706513 | I10: =(D10-D9)/D9 -> 0.027046784 | J10: =(E10-E9)/E9 -> 0.0094046386 | K10: =(F10-F9)/F9 -> 0.023529412
A11: 44302 | B11: 2099.8999 | C11: 1783.3276 | D11: 1434.95 | E11: 646.05 | F11: 1360.5 | G11: =(B11-B10)/B10 -> 0.0078713223 | H11: =(C11-C10)/C10 -> -0.0062748097 | I11: =(D11-D10)/D10 -> 0.021316726 | J11: =(E11-E10)/E10 -> 0.020213186 | K11: =(F11-F10)/F10 -> -0.013379745
A12: 44305 | B12: 2027.6 | C12: 1755.2684 | D12: 1390 | E12: 640.65 | F12: 1340 | G12: =(B12-B11)/B11 -> -0.034430165 | H12: =(C12-C11)/C11 -> -0.015734181 | I12: =(D12-D11)/D11 -> -0.031325133 | J12: =(E12-E11)/E11 -> -0.0083584862 | K12: =(F12-F11)/F11 -> -0.01506799
A13: 44306 | B13: 2020.15 | C13: 1754.7609 | D13: 1425 | E13: 645.15 | F13: 1320 | G13: =(B13-B12)/B12 -> -0.0036742947 | H13: =(C13-C12)/C12 -> -0.00028912957 | I13: =(D13-D12)/D12 -> 0.025179856 | J13: =(E13-E12)/E12 -> 0.0070241161 | K13: =(F13-F12)/F12 -> -0.014925373
A14: 44308 | B14: 2033 | C14: 1759.6066 | D14: 1380 | E14: 639.95 | F14: 1310 | G14: =(B14-B13)/B13 -> 0.0063609138 | H14: =(C14-C13)/C13 -> 0.0027614588 | I14: =(D14-D13)/D13 -> -0.031578947 | J14: =(E14-E13)/E13 -> -0.0080601411 | K14: =(F14-F13)/F13 -> -0.0075757576
... A16: 44312 | B16: 1977.5 | C16: 1788.6349 | D16: 1413 | E16: 634.7 | F16: 1330.05 | G16: =(B16-B15)/B15 -> 0.0039854797 | H16: =(C16-C15)/C15 -> 0.017591253 | I16: =(D16-D15)/D15 -> 0.0028388928 | J16: =(E16-E15)/E15 -> -0.0050944431 | K16: =(F16-F15)/F15 -> 3.7593985e-05
A17: 44313 | B17: 2014.8 | C17: 1835.5233 | D17: 1407.25 | E17: 639.25 | F17: 1339 | G17: =(B17-B16)/B16 -> 0.0188622 | H17: =(C17-C16)/C16 -> 0.026214629 | I17: =(D17-D16)/D16 -> -0.004069356 | J17: =(E17-E16)/E16 -> 0.0071687411 | K17: =(F17-F16)/F16 -> 0.0067290703 | N17: COVARIANCE MATRIX
A18: 44314 | B18: 2051.1499 | C18: 1843.5072 | D18: 1436.25 | E18: 643.4 | F18: 1384.85 | G18: =(B18-B17)/B17 -> 0.018041443 | H18: =(C18-C17)/C17 -> 0.0043496588 | I18: =(D18-D17)/D17 -> 0.020607568 | J18: =(E18-E17)/E17 -> 0.0064919828 | K18: =(F18-F17)/F17 -> 0.034241972 | O18: BASF | P18: Reliance | Q18: HDFC | R18: SUNPHARMA | S18: LT
A19: 44315 | B19: 2073.95 | C19: 1868.1975 | D19: 1486.2 | E19: 644.5 | F19: 1383.95 | G19: =(B19-B18)/B18 -> 0.011115765 | H19: =(C19-C18)/C18 -> 0.013393113 | I19: =(D19-D18)/D18 -> 0.034778068 | J19: =(E19-E18)/E18 -> 0.0017096674 | K19: =(F19-F18)/F18 -> -0.00064988988 | N19: BASF | O19: =VARP('Sheet 3'!$G$3:$G$741) -> 0.0004082621 | P19: 5.203688e-05 | Q19: 2.1424072e-05 | R19: 4.4366469e-05 | S19: 2.6676503e-05
A20: 44316 | B20: 2228.75 | C20: 1840.9229 | D20: 1445 | E20: 654.45 | F20: 1350 | G20: =(B20-B19)/B19 -> 0.074640179 | H20: =(C20-C19)/C19 -> -0.01459942 | I20: =(D20-D19)/D19 -> -0.027721706 | J20: =(E20-E19)/E19 -> 0.015438324 | K20: =(F20-F19)/F19 -> -0.024531233 | N20: Reliance | O20: 5.203688e-05 | P20: =VARP('Sheet 3'!$H$3:$H$741) -> 0.00021075539 | Q20: 2.4683269e-05 | R20: 3.66307e-05 | S20: 2.3076458e-05
A21: 44319 | B21: 2282.8999 | C21: 1808.2025 | D21: 1393 | E21: 659.2 | F21: 1325.5 | G21: =(B21-B20)/B20 -> 0.024296085 | H21: =(C21-C20)/C20 -> -0.017773911 | I21: =(D21-D20)/D20 -> -0.035986159 | J21: =(E21-E20)/E20 -> 0.0072580029 | K21: =(F21-F20)/F20 -> -0.018148148 | N21: HDFC | O21: 2.1424072e-05 | P21: 2.4683269e-05 | Q21: =VARP('Sheet 3'!$I$3:$I$741) -> 0.00022118063 | R21: 8.6026014e-06 | S21: 7.5230812e-05
A22: 44320 | B22: 2281.55 | C22: 1769.0211 | D22: 1409.95 | E22: 645.15 | F22: 1350 | G22: =(B22-B21)/B21 -> -0.00059130933 | H22: =(C22-C21)/C21 -> -0.021668701 | I22: =(D22-D21)/D21 -> 0.012167983 | J22: =(E22-E21)/E21 -> -0.021313714 | K22: =(F22-F21)/F21 -> 0.018483591 | N22: SUNPHARMA | O22: 4.4366469e-05 | P22: 3.66307e-05 | Q22: 8.6026014e-06 | R22: =VARP('Sheet 3'!$J$3:$J$741) -> 0.00017753864 | S22: 7.7587245e-07
A23: 44321 | B23: 2320.7 | C23: 1772.2517 | D23: 1401 | E23: 683.4 | F23: 1342.2 | G23: =(B23-B22)/B22 -> 0.017159387 | H23: =(C23-C22)/C22 -> 0.0018262077 | I23: =(D23-D22)/D22 -> -0.0063477428 | J23: =(E23-E22)/E22 -> 0.059288538 | K23: =(F23-F22)/F22 -> -0.0057777778 | N23: LT | O23: 2.6676503e-05 | P23: 2.3076458e-05 | Q23: 7.5230812e-05 | R23: 7.7587245e-07 | S23: =VARP('Sheet 3'!$K$3:$K$741) -> 0.00021097305
A24: 44322 | B24: 2294.8999 | C24: 1782.3124 | D24: 1407.6 | E24: 679.4 | F24: 1344 | G24: =(B24-B23)/B23 -> -0.011117378 | H24: =(C24-C23)/C23 -> 0.0056767896 | I24: =(D24-D23)/D23 -> 0.0047109208 | J24: =(E24-E23)/E23 -> -0.0058530875 | K24: =(F24-F23)/F23 -> 0.0013410818
A25: 44323 | B25: 2451.7 | C25: 1783.0046 | D25: 1412.95 | E25: 679.45 | F25: 1347 | G25: =(B25-B24)/B24 -> 0.068325464 | H25: =(C25-C24)/C24 -> 0.00038837187 | I25: =(D25-D24)/D24 -> 0.0038007957 | J25: =(E25-E24)/E24 -> 7.3594348e-05 | K25: =(F25-F24)/F24 -> 0.0022321429
